Workbook

Sheet Start Here
A1: DIPZ Business Tracker
A2: Record sales and expenses. Profit, loan balance and checks calculate on their own.
A4: How to use it
A5: 1. After each selling session, add ONE row in the 'Daily Sales' sheet. Fill only the yellow columns (A to J).
A6: 2. Every time you spend money or pay someone, add ONE row in the 'Expenses' sheet. Fill only the yellow columns (A to F).
A7: 3. Open the 'Dashboard' sheet, pick a month, and see revenue, expenses, profit, the loan balance and any warnings.
A8: 4. 'Monthly Summary' shows all 12 months side by side. 'Loan' shows your repayment schedule. You do not type in these two.
A10: Colour guide
A11: Yellow cell = type here
A12: Grey cell = automatic, do not type
A13: Red CHECK = the numbers do not add up, look at that row
A15: Rules that keep the numbers right
... A27: First, go to the Settings sheet and check the yellow cells: your tracking start month, prices, venue shares and loan details.

Sheet Dashboard
A1: Dashboard
A2: Pick a month to see it. The year-to-date block covers all months.
A3: Month to show (pick from the list) | B3: 46327
A4: Month position (helper) | B4: =IFERROR(MATCH(B3,'Monthly Summary'!B5:M5,0),0) -> 1
A6: Selected month
A7: Revenue | B7: =IFERROR(INDEX('Monthly Summary'!$B$10:$M$10,$B$4),0) -> 90200
A8: Venue share | B8: =IFERROR(INDEX('Monthly Summary'!$B$11:$M$11,$B$4),0) -> 9020
A9: Operating expenses | B9: =IFERROR(INDEX('Monthly Summary'!$B$24:$M$24,$B$4),0) -> 0
A10: Operating profit | B10: =IFERROR(INDEX('Monthly Summary'!$B$26:$M$26,$B$4),0) -> 81180
A11: Loan installments paid | B11: =IFERROR(INDEX('Monthly Summary'!$B$27:$M$27,$B$4),0) -> 0
A12: Net profit after loan | B12: =IFERROR(INDEX('Monthly Summary'!$B$28:$M$28,$B$4),0) -> 81180
A13: Net margin | B13: =IFERROR(INDEX('Monthly Summary'!$B$29:$M$29,$B$4),0) -> 0.9
A14: Units sold | B14: =IFERROR(INDEX('Monthly Summary'!$B$8:$M$8,$B$4),0) -> 167
A15: Average units per session | B15: =IFERROR(INDEX('Monthly Summary'!$B$39:$M$39,$B$4),0) -> 41.75
A16: Average selling price | B16: =IFERROR(INDEX('Monthly Summary'!$B$36:$M$36,$B$4),0) -> 540.11976
A17: Actual cost per unit | B17: =IFERROR(INDEX('Monthly Summary'!$B$37:$M$37,$B$4),0) -> 0
A18: Units as % of plan | B18: =IFERROR(INDEX('Monthly Summary'!$B$41:$M$41,$B$4),0) -> 0.15829384
A19: Stock checks flagged | B19: =IFERROR(INDEX('Monthly Summary'!$B$42:$M$42,$B$4),0) -> 0
A20: Money checks flagged | B20: =IFERROR(INDEX('Monthly Summary'!$B$43:$M$43,$B$4),0) -> 0
A22: Year to date (all months)
A23: Revenue | B23: ='Monthly Summary'!N10 -> 90200
A24: Operating expenses | B24: ='Monthly Summary'!N24 -> 0
A25: Net profit after loan | B25: ='Monthly Summary'!N28 -> 81180
A26: Capital spent so far | B26: ='Monthly Summary'!N31 -> 0
A27: Startup budget | B27: =Settings!B10 -> 460000
A28: Startup budget used | B28: =IF(B27=0,0,B26/B27) -> 0
A29: Share of capital spent earned back by profit | B29: =IF(B26=0,0,B25/B26) -> 0
A30: Loan balance remaining | B30: =Loan!B10 -> 500000
A31: Installments paid | B31: =Loan!B8 -> 0
A33: Data warnings (all months, should all be 0)
A34: Expense rows with a category to fix | B34: =COUNTIF(Expenses!$G$6:$G$2005,"Check category") -> 0
A35: Sales rows with a venue not in the Settings list | B35: =SUMPRODUCT(('Daily Sales'!$A$6:$A$1005<>"")*(COUNTIF(Settings!$A$30:$A$36,'Daily Sales'!$B$6:$B$1005)=0)) -> 0
A36: If a flag is not 0, open Daily Sales or Expenses and look for the red cells.

Sheet Settings
A1: Settings
A2: Yellow cells are yours to change. Everything else in the workbook reads from here.
A4: General
A5: Business name | B5: DIPZ
A6: First month to track (type the 1st of the month) | B6: 46327
A7: Plan: units per month | B7: 1055 | C7: From your profit plan
A8: Plan: net profit per month | B8: 261818 | C8: From your profit plan
A9: Plan: cost per unit (ingredients and packaging) | B9: 150 | C9: From you
A10: Startup budget (capital and launch spend) | B10: 460000 | C10: From you: cart 260k, freezer 100k, equipment 25k, marketing 25k, videos 50k
A12: Loan
A13: Loan amount | B13: 500000
A14: Annual interest rate | B14: 0.12 | C14: Indicative. Replace with the bank's actual rate.
A15: Term (months) | B15: 36 | C15: Indicative. Replace with the bank's actual term.
A16: First installment date | B16: 46357
A17: Monthly installment | B17: =-PMT(B14/12,B15,B13) -> 16607.155
A19: Price list (add a new row when prices change)
A20: Effective from | B20: Standard price | C20: Premium price
A21: 46327 | B21: 500 | C21: 600
A26: The first row must start on or before your first selling day. Keep the dates in order, oldest first.
A28: Venues (revenue share the venue takes)
A29: Venue | B29: Venue share %
A30: Shakshuka Food Park | B30: 0.1 | C30: From the venue's stated terms
A31: BMICH event | B31: 0 | C31: Stall fees are not a share, so record them in Expenses
A32: Other venue | B32: 0
A38: Expense categories
A39: Category | B39: Type
A40: Type must be Operating, Capital, Loan or Owner. Operating counts against profit. Do not change the first 12 rows' types.
A41: Ingredients | B41: Operating
A42: Packaging | B42: Operating
A43: Staff pay | B43: Operating
A44: Utilities | B44: Operating
A45: Marketing | B45: Operating
A46: Transport | B46: Operating
A47: Repairs and supplies | B47: Operating
A48: Permits and registration | B48: Operating
A49: Other operating | B49: Operating
A50: Equipment and cart (startup) | B50: Capital
A51: Loan installment | B51: Loan
A52: Owner withdrawal | B52: Owner
A57: Payment methods
...

Sheet Daily Sales
A1: Daily Sales
A2: One row per venue per day. Fill the yellow columns only. Grey columns calculate by themselves.
A4: Date | B4: Venue | C4: Standard sold | D4: Premium sold | E4: Free units given | F4: Bananas at start | G4: Bananas left | H4: Cash collected | I4: Digital payments | J4: Notes | K4: Units sold | L4: Revenue | M4: Venue share | N4: Stock gap | O4: Stock check | P4: Money gap | Q4: Money check
A5: 46328 | B5: Shakshuka Food Park | C5: 12 | D5: 8 | E5: 2 | F5: 40 | G5: 18 | H5: 6800 | I5: 4000 | J5: EXAMPLE ROW, not counted | K5: 20 | L5: 10800 | M5: 1080 | N5: 0 | O5: OK | P5: 0 | Q5: OK
A6: 46330 | B6: Shakshuka Food Park | C6: 33 | D6: 24 | E6: 1 | F6: 60 | G6: 2 | H6: 30900 | I6: 0 | K6: =IF($A6="","",C6+D6) -> 57 | L6: =IF($A6="","",C6*SUMIFS(Settings!$B$21:$B$25,Settings!$A$21:$A$25,SUMPRODUCT(MAX((Settings!$A$21:$A$25<=$A6)*Settings!$A$21:$A$25)))+D6*SUMIFS(Settings!$C$21:$C$25,Settings!$A$21:$A$25,SUMPRODUCT(MAX((Settings!$A$21:$A$25<=$A6)*Settings!$A$21:$A$25)))) -> 30900 | M6: =IF($A6="","",L6*IFERROR(INDEX(Settings!$B$30:$B$36,MATCH($B6,Settings!$A$30:$A$36,0)),0)) -> 3090 | N6: =IF(OR($A6="",F6="",G6=""),"",(F6-G6)-(K6+E6)) -> 0 | O6: =IF(N6="","",IF(N6=0,"OK","CHECK")) -> OK | P6: =IF(OR($A6="",AND(H6="",I6="")),"",H6+I6-L6) -> 0 | Q6: =IF(P6="","",IF(P6=0,"OK","CHECK")) -> OK
A7: 46331 | B7: Shakshuka Food Park | C7: 12 | D7: 7 | E7: 1 | F7: 60 | G7: 40 | H7: =SUM(C7*500+D7*600) -> 10200 | K7: =IF($A7="","",C7+D7) -> 19 | L7: =IF($A7="","",C7*SUMIFS(Settings!$B$21:$B$25,Settings!$A$21:$A$25,SUMPRODUCT(MAX((Settings!$A$21:$A$25<=$A7)*Settings!$A$21:$A$25)))+D7*SUMIFS(Settings!$C$21:$C$25,Settings!$A$21:$A$25,SUMPRODUCT(MAX((Settings!$A$21:$A$25<=$A7)*Settings!$A$21:$A$25)))) -> 10200 | M7: =IF($A7="","",L7*IFERROR(INDEX(Settings!$B$30:$B$36,MATCH($B7,Settings!$A$30:$A$36,0)),0)) -> 1020 | N7: =IF(OR($A7="",F7="",G7=""),"",(F7-G7)-(K7+E7)) -> 0 | O7: =IF(N7="","",IF(N7=0,"OK","CHECK")) -> OK | P7: =IF(OR($A7="",AND(H7="",I7="")),"",H7+I7-L7) -> 0 | Q7: =IF(P7="","",IF(P7=0,"OK","CHECK")) -> OK
A8: 46332 | B8: Shakshuka Food Park | C8: 10 | D8: 6 | E8: 1 | F8: 60 | G8: 43 | H8: =SUM(C8*500+D8*600) -> 8600 | K8: =IF($A8="","",C8+D8) -> 16 | L8: =IF($A8="","",C8*SUMIFS(Settings!$B$21:$B$25,Settings!$A$21:$A$25,SUMPRODUCT(MAX((Settings!$A$21:$A$25<=$A8)*Settings!$A$21:$A$25)))+D8*SUMIFS(Settings!$C$21:$C$25,Settings!$A$21:$A$25,SUMPRODUCT(MAX((Settings!$A$21:$A$25<=$A8)*Settings!$A$21:$A$25)))) -> 8600 | M8: =IF($A8="","",L8*IFERROR(INDEX(Settings!$B$30:$B$36,MATCH($B8,Settings!$A$30:$A$36,0)),0)) -> 860 | N8: =IF(OR($A8="",F8="",G8=""),"",(F8-G8)-(K8+E8)) -> 0 | O8: =IF(N8="","",IF(N8=0,"OK","CHECK")) -> OK | P8: =IF(OR($A8="",AND(H8="",I8="")),"",H8+I8-L8) -> 0 | Q8: =IF(P8="","",IF(P8=0,"OK","CHECK")) -> OK
A9: 46333 | B9: Shakshuka Food Park | C9: 45 | D9: 30 | E9: 1 | F9: 80 | G9: 4 | H9: =SUM(C9*500+D9*600) -> 40500 | K9: =IF($A9="","",C9+D9) -> 75 | L9: =IF($A9="","",C9*SUMIFS(Settings!$B$21:$B$25,Settings!$A$21:$A$25,SUMPRODUCT(MAX((Settings!$A$21:$A$25<=$A9)*Settings!$A$21:$A$25)))+D9*SUMIFS(Settings!$C$21:$C$25,Settings!$A$21:$A$25,SUMPRODUCT(MAX((Settings!$A$21:$A$25<=$A9)*Settings!$A$21:$A$25)))) -> 40500 | M9: =IF($A9="","",L9*IFERROR(INDEX(Settings!$B$30:$B$36,MATCH($B9,Settings!$A$30:$A$36,0)),0)) -> 4050 | N9: =IF(OR($A9="",F9="",G9=""),"",(F9-G9)-(K9+E9)) -> 0 | O9: =IF(N9="","",IF(N9=0,"OK","CHECK")) -> OK | P9: =IF(OR($A9="",AND(H9="",I9="")),"",H9+I9-L9) -> 0 | Q9: =IF(P9="","",IF(P9=0,"OK","CHECK")) -> OK
A10: 46304 | B10: Shakshuka Food Park | C10: 12 | D10: 8 | E10: 0 | F10: 0 | G10: 0 | H10: 6000 | I10: 4000 | J10: Test sync order | K10: =IF($A10="","",C10+D10) | L10: =IF($A10="","",C10*SUMIFS(Settings!$B$21:$B$25,Settings!$A$21:$A$25,SUMPRODUCT(MAX((Settings!$A$21:$A$25<=$A10)*Settings!$A$21:$A$25)))+D10*SUMIFS(Settings!$C$21:$C$25,Settings!$A$21:$A$25,SUMPRODUCT(MAX((Settings!$A$21:$A$25<=$A10)*Settings!$A$21:$A$25)))) | M10: =IF($A10="","",L10*IFERROR(INDEX(Settings!$B$30:$B$36,MATCH($B10,Settings!$A$30:$A$36,0)),0)) | N10: =IF(OR($A10="",F10="",G10=""),"",(F10-G10)-(K10+E10)) | O10: =IF(N10="","",IF(N10=0,"OK","CHECK")) | P10: =IF(OR($A10="",AND(H10="",I10="")),"",H10+I10-L10) | Q10: =IF(P10="","",IF(P10=0,"OK","CHECK"))
K11: =IF($A11="","",C11+D11) | L11: =IF($A11="","",C11*SUMIFS(Settings!$B$21:$B$25,Settings!$A$21:$A$25,SUMPRODUCT(MAX((Settings!$A$21:$A$25<=$A11)*Settings!$A$21:$A$25)))+D11*SUMIFS(Settings!$C$21:$C$25,Settings!$A$21:$A$25,SUMPRODUCT(MAX((Settings!$A$21:$A$25<=$A11)*Settings!$A$21:$A$25)))) | M11: =IF($A11="","",L11*IFERROR(INDEX(Settings!$B$30:$B$36,MATCH($B11,Settings!$A$30:$A$36,0)),0)) | N11: =IF(OR($A11="",F11="",G11=""),"",(F11-G11)-(K11+E11)) | O11: =IF(N11="","",IF(N11=0,"OK","CHECK")) | P11: =IF(OR($A11="",AND(H11="",I11="")),"",H11+I11-L11) | Q11: =IF(P11="","",IF(P11=0,"OK","CHECK"))
K12: =IF($A12="","",C12+D12) | L12: =IF($A12="","",C12*SUMIFS(Settings!$B$21:$B$25,Settings!$A$21:$A$25,SUMPRODUCT(MAX((Settings!$A$21:$A$25<=$A12)*Settings!$A$21:$A$25)))+D12*SUMIFS(Settings!$C$21:$C$25,Settings!$A$21:$A$25,SUMPRODUCT(MAX((Settings!$A$21:$A$25<=$A12)*Settings!$A$21:$A$25)))) | M12: =IF($A12="","",L12*IFERROR(INDEX(Settings!$B$30:$B$36,MATCH($B12,Settings!$A$30:$A$36,0)),0)) | N12: =IF(OR($A12="",F12="",G12=""),"",(F12-G12)-(K12+E12)) | O12: =IF(N12="","",IF(N12=0,"OK","CHECK")) | P12: =IF(OR($A12="",AND(H12="",I12="")),"",H12+I12-L12) | Q12: =IF(P12="","",IF(P12=0,"OK","CHECK"))
K13: =IF($A13="","",C13+D13) | L13: =IF($A13="","",C13*SUMIFS(Settings!$B$21:$B$25,Settings!$A$21:$A$25,SUMPRODUCT(MAX((Settings!$A$21:$A$25<=$A13)*Settings!$A$21:$A$25)))+D13*SUMIFS(Settings!$C$21:$C$25,Settings!$A$21:$A$25,SUMPRODUCT(MAX((Settings!$A$21:$A$25<=$A13)*Settings!$A$21:$A$25)))) | M13: =IF($A13="","",L13*IFERROR(INDEX(Settings!$B$30:$B$36,MATCH($B13,Settings!$A$30:$A$36,0)),0)) | N13: =IF(OR($A13="",F13="",G13=""),"",(F13-G13)-(K13+E13)) | O13: =IF(N13="","",IF(N13=0,"OK","CHECK")) | P13: =IF(OR($A13="",AND(H13="",I13="")),"",H13+I13-L13) | Q13: =IF(P13="","",IF(P13=0,"OK","CHECK"))
K14: =IF($A14="","",C14+D14) | L14: =IF($A14="","",C14*SUMIFS(Settings!$B$21:$B$25,Settings!$A$21:$A$25,SUMPRODUCT(MAX((Settings!$A$21:$A$25<=$A14)*Settings!$A$21:$A$25)))+D14*SUMIFS(Settings!$C$21:$C$25,Settings!$A$21:$A$25,SUMPRODUCT(MAX((Settings!$A$21:$A$25<=$A14)*Settings!$A$21:$A$25)))) | M14: =IF($A14="","",L14*IFERROR(INDEX(Settings!$B$30:$B$36,MATCH($B14,Settings!$A$30:$A$36,0)),0)) | N14: =IF(OR($A14="",F14="",G14=""),"",(F14-G14)-(K14+E14)) | O14: =IF(N14="","",IF(N14=0,"OK","CHECK")) | P14: =IF(OR($A14="",AND(H14="",I14="")),"",H14+I14-L14) | Q14: =IF(P14="","",IF(P14=0,"OK","CHECK"))
K15: =IF($A15="","",C15+D15) | L15: =IF($A15="","",C15*SUMIFS(Settings!$B$21:$B$25,Settings!$A$21:$A$25,SUMPRODUCT(MAX((Settings!$A$21:$A$25<=$A15)*Settings!$A$21:$A$25)))+D15*SUMIFS(Settings!$C$21:$C$25,Settings!$A$21:$A$25,SUMPRODUCT(MAX((Settings!$A$21:$A$25<=$A15)*Settings!$A$21:$A$25)))) | M15: =IF($A15="","",L15*IFERROR(INDEX(Settings!$B$30:$B$36,MATCH($B15,Settings!$A$30:$A$36,0)),0)) | N15: =IF(OR($A15="",F15="",G15=""),"",(F15-G15)-(K15+E15)) | O15: =IF(N15="","",IF(N15=0,"OK","CHECK")) | P15: =IF(OR($A15="",AND(H15="",I15="")),"",H15+I15-L15) | Q15: =IF(P15="","",IF(P15=0,"OK","CHECK"))
K16: =IF($A16="","",C16+D16) | L16: =IF($A16="","",C16*SUMIFS(Settings!$B$21:$B$25,Settings!$A$21:$A$25,SUMPRODUCT(MAX((Settings!$A$21:$A$25<=$A16)*Settings!$A$21:$A$25)))+D16*SUMIFS(Settings!$C$21:$C$25,Settings!$A$21:$A$25,SUMPRODUCT(MAX((Settings!$A$21:$A$25<=$A16)*Settings!$A$21:$A$25)))) | M16: =IF($A16="","",L16*IFERROR(INDEX(Settings!$B$30:$B$36,MATCH($B16,Settings!$A$30:$A$36,0)),0)) | N16: =IF(OR($A16="",F16="",G16=""),"",(F16-G16)-(K16+E16)) | O16: =IF(N16="","",IF(N16=0,"OK","CHECK")) | P16: =IF(OR($A16="",AND(H16="",I16="")),"",H16+I16-L16) | Q16: =IF(P16="","",IF(P16=0,"OK","CHECK"))
K17: =IF($A17="","",C17+D17) | L17: =IF($A17="","",C17*SUMIFS(Settings!$B$21:$B$25,Settings!$A$21:$A$25,SUMPRODUCT(MAX((Settings!$A$21:$A$25<=$A17)*Settings!$A$21:$A$25)))+D17*SUMIFS(Settings!$C$21:$C$25,Settings!$A$21:$A$25,SUMPRODUCT(MAX((Settings!$A$21:$A$25<=$A17)*Settings!$A$21:$A$25)))) | M17: =IF($A17="","",L17*IFERROR(INDEX(Settings!$B$30:$B$36,MATCH($B17,Settings!$A$30:$A$36,0)),0)) | N17: =IF(OR($A17="",F17="",G17=""),"",(F17-G17)-(K17+E17)) | O17: =IF(N17="","",IF(N17=0,"OK","CHECK")) | P17: =IF(OR($A17="",AND(H17="",I17="")),"",H17+I17-L17) | Q17: =IF(P17="","",IF(P17=0,"OK","CHECK"))
K18: =IF($A18="","",C18+D18) | L18: =IF($A18="","",C18*SUMIFS(Settings!$B$21:$B$25,Settings!$A$21:$A$25,SUMPRODUCT(MAX((Settings!$A$21:$A$25<=$A18)*Settings!$A$21:$A$25)))+D18*SUMIFS(Settings!$C$21:$C$25,Settings!$A$21:$A$25,SUMPRODUCT(MAX((Settings!$A$21:$A$25<=$A18)*Settings!$A$21:$A$25)))) | M18: =IF($A18="","",L18*IFERROR(INDEX(Settings!$B$30:$B$36,MATCH($B18,Settings!$A$30:$A$36,0)),0)) | N18: =IF(OR($A18="",F18="",G18=""),"",(F18-G18)-(K18+E18)) | O18: =IF(N18="","",IF(N18=0,"OK","CHECK")) | P18: =IF(OR($A18="",AND(H18="",I18="")),"",H18+I18-L18) | Q18: =IF(P18="","",IF(P18=0,"OK","CHECK"))
K19: =IF($A19="","",C19+D19) | L19: =IF($A19="","",C19*SUMIFS(Settings!$B$21:$B$25,Settings!$A$21:$A$25,SUMPRODUCT(MAX((Settings!$A$21:$A$25<=$A19)*Settings!$A$21:$A$25)))+D19*SUMIFS(Settings!$C$21:$C$25,Settings!$A$21:$A$25,SUMPRODUCT(MAX((Settings!$A$21:$A$25<=$A19)*Settings!$A$21:$A$25)))) | M19: =IF($A19="","",L19*IFERROR(INDEX(Settings!$B$30:$B$36,MATCH($B19,Settings!$A$30:$A$36,0)),0)) | N19: =IF(OR($A19="",F19="",G19=""),"",(F19-G19)-(K19+E19)) | O19: =IF(N19="","",IF(N19=0,"OK","CHECK")) | P19: =IF(OR($A19="",AND(H19="",I19="")),"",H19+I19-L19) | Q19: =IF(P19="","",IF(P19=0,"OK","CHECK"))
K20: =IF($A20="","",C20+D20) | L20: =IF($A20="","",C20*SUMIFS(Settings!$B$21:$B$25,Settings!$A$21:$A$25,SUMPRODUCT(MAX((Settings!$A$21:$A$25<=$A20)*Settings!$A$21:$A$25)))+D20*SUMIFS(Settings!$C$21:$C$25,Settings!$A$21:$A$25,SUMPRODUCT(MAX((Settings!$A$21:$A$25<=$A20)*Settings!$A$21:$A$25)))) | M20: =IF($A20="","",L20*IFERROR(INDEX(Settings!$B$30:$B$36,MATCH($B20,Settings!$A$30:$A$36,0)),0)) | N20: =IF(OR($A20="",F20="",G20=""),"",(F20-G20)-(K20+E20)) | O20: =IF(N20="","",IF(N20=0,"OK","CHECK")) | P20: =IF(OR($A20="",AND(H20="",I20="")),"",H20+I20-L20) | Q20: =IF(P20="","",IF(P20=0,"OK","CHECK"))
K21: =IF($A21="","",C21+D21) | L21: =IF($A21="","",C21*SUMIFS(Settings!$B$21:$B$25,Settings!$A$21:$A$25,SUMPRODUCT(MAX((Settings!$A$21:$A$25<=$A21)*Settings!$A$21:$A$25)))+D21*SUMIFS(Settings!$C$21:$C$25,Settings!$A$21:$A$25,SUMPRODUCT(MAX((Settings!$A$21:$A$25<=$A21)*Settings!$A$21:$A$25)))) | M21: =IF($A21="","",L21*IFERROR(INDEX(Settings!$B$30:$B$36,MATCH($B21,Settings!$A$30:$A$36,0)),0)) | N21: =IF(OR($A21="",F21="",G21=""),"",(F21-G21)-(K21+E21)) | O21: =IF(N21="","",IF(N21=0,"OK","CHECK")) | P21: =IF(OR($A21="",AND(H21="",I21="")),"",H21+I21-L21) | Q21: =IF(P21="","",IF(P21=0,"OK","CHECK"))
K22: =IF($A22="","",C22+D22) | L22: =IF($A22="","",C22*SUMIFS(Settings!$B$21:$B$25,Settings!$A$21:$A$25,SUMPRODUCT(MAX((Settings!$A$21:$A$25<=$A22)*Settings!$A$21:$A$25)))+D22*SUMIFS(Settings!$C$21:$C$25,Settings!$A$21:$A$25,SUMPRODUCT(MAX((Settings!$A$21:$A$25<=$A22)*Settings!$A$21:$A$25)))) | M22: =IF($A22="","",L22*IFERROR(INDEX(Settings!$B$30:$B$36,MATCH($B22,Settings!$A$30:$A$36,0)),0)) | N22: =IF(OR($A22="",F22="",G22=""),"",(F22-G22)-(K22+E22)) | O22: =IF(N22="","",IF(N22=0,"OK","CHECK")) | P22: =IF(OR($A22="",AND(H22="",I22="")),"",H22+I22-L22) | Q22: =IF(P22="","",IF(P22=0,"OK","CHECK"))
... K1005: =IF($A1005="","",C1005+D1005) | L1005: =IF($A1005="","",C1005*SUMIFS(Settings!$B$21:$B$25,Settings!$A$21:$A$25,SUMPRODUCT(MAX((Settings!$A$21:$A$25<=$A1005)*Settings!$A$21:$A$25)))+D1005*SUMIFS(Settings!$C$21:$C$25,Settings!$A$21:$A$25,SUMPRODUCT(MAX((Settings!$A$21:$A$25<=$A1005)*Settings!$A$21:$A$25)))) | M1005: =IF($A1005="","",L1005*IFERROR(INDEX(Settings!$B$30:$B$36,MATCH($B1005,Settings!$A$30:$A$36,0)),0)) | N1005: =IF(OR($A1005="",F1005="",G1005=""),"",(F1005-G1005)-(K1005+E1005)) | O1005: =IF(N1005="","",IF(N1005=0,"OK","CHECK")) | P1005: =IF(OR($A1005="",AND(H1005="",I1005="")),"",H1005+I1005-L1005) | Q1005: =IF(P1005="","",IF(P1005=0,"OK","CHECK"))

Sheet Expenses
A1: Expenses
A2: One row per payment. Fill the yellow columns only. The Type column fills itself from the category.
A4: Date | B4: Category | C4: What it was for | D4: Amount (LKR) | E4: Paid from | F4: Notes | G4: Type
A5: 46327 | B5: Ingredients | C5: Bananas for 2 days | D5: 4500 | E5: Cash | F5: EXAMPLE ROW, not counted | G5: Operating
G6: =IF($B6="","",IFERROR(INDEX(Settings!$B$41:$B$55,MATCH($B6,Settings!$A$41:$A$55,0)),"Check category"))
G7: =IF($B7="","",IFERROR(INDEX(Settings!$B$41:$B$55,MATCH($B7,Settings!$A$41:$A$55,0)),"Check category"))
G8: =IF($B8="","",IFERROR(INDEX(Settings!$B$41:$B$55,MATCH($B8,Settings!$A$41:$A$55,0)),"Check category"))
G9: =IF($B9="","",IFERROR(INDEX(Settings!$B$41:$B$55,MATCH($B9,Settings!$A$41:$A$55,0)),"Check category"))
G10: =IF($B10="","",IFERROR(INDEX(Settings!$B$41:$B$55,MATCH($B10,Settings!$A$41:$A$55,0)),"Check category"))
G11: =IF($B11="","",IFERROR(INDEX(Settings!$B$41:$B$55,MATCH($B11,Settings!$A$41:$A$55,0)),"Check category"))
G12: =IF($B12="","",IFERROR(INDEX(Settings!$B$41:$B$55,MATCH($B12,Settings!$A$41:$A$55,0)),"Check category"))
G13: =IF($B13="","",IFERROR(INDEX(Settings!$B$41:$B$55,MATCH($B13,Settings!$A$41:$A$55,0)),"Check category"))
G14: =IF($B14="","",IFERROR(INDEX(Settings!$B$41:$B$55,MATCH($B14,Settings!$A$41:$A$55,0)),"Check category"))
G15: =IF($B15="","",IFERROR(INDEX(Settings!$B$41:$B$55,MATCH($B15,Settings!$A$41:$A$55,0)),"Check category"))
G16: =IF($B16="","",IFERROR(INDEX(Settings!$B$41:$B$55,MATCH($B16,Settings!$A$41:$A$55,0)),"Check category"))
G17: =IF($B17="","",IFERROR(INDEX(Settings!$B$41:$B$55,MATCH($B17,Settings!$A$41:$A$55,0)),"Check category"))
... G2005: =IF($B2005="","",IFERROR(INDEX(Settings!$B$41:$B$55,MATCH($B2005,Settings!$A$41:$A$55,0)),"Check category"))

Sheet Loan
A1: Loan
A2: Schedule from your Settings. The balance moves each time you record an installment in Expenses.
A3: Loan amount | B3: =Settings!B13 -> 500000
A4: Annual interest rate | B4: =Settings!B14 -> 0.12
A5: Term (months) | B5: =Settings!B15 -> 36
A6: Monthly installment | B6: =Settings!B17 -> 16607.155
A7: Total interest over the loan | B7: =B6*B5-B3 -> 97857.577
A8: Installments recorded in Expenses | B8: =COUNTIF(Expenses!$G$6:$G$2005,"Loan") -> 0
A9: Total repaid so far | B9: =SUMIFS(Expenses!$D$6:$D$2005,Expenses!$G$6:$G$2005,"Loan") -> 0
A10: Estimated balance remaining | B10: =IF(B8=0,B3,IF(B8>=B5,0,INDEX(G15:G74,B8))) -> 500000 | C10: Based on the number of installments recorded, following the schedule below.
A14: No. | B14: Due date | C14: Opening balance | D14: Interest | E14: Principal | F14: Installment | G14: Closing balance
A15: 1 | B15: =IF($A15>Settings!$B$15,"",EDATE(Settings!$B$16,$A15-1)) -> 46357 | C15: =IF($A15>Settings!$B$15,"",Settings!$B$13) -> 500000 | D15: =IF($A15>Settings!$B$15,"",C15*Settings!$B$14/12) -> 5000 | E15: =IF($A15>Settings!$B$15,"",F15-D15) -> 11607.155 | F15: =IF($A15>Settings!$B$15,"",Settings!$B$17) -> 16607.155 | G15: =IF($A15>Settings!$B$15,"",C15-E15) -> 488392.85
A16: 2 | B16: =IF($A16>Settings!$B$15,"",EDATE(Settings!$B$16,$A16-1)) -> 46388 | C16: =IF($A16>Settings!$B$15,"",G15) -> 488392.85 | D16: =IF($A16>Settings!$B$15,"",C16*Settings!$B$14/12) -> 4883.9285 | E16: =IF($A16>Settings!$B$15,"",F16-D16) -> 11723.226 | F16: =IF($A16>Settings!$B$15,"",Settings!$B$17) -> 16607.155 | G16: =IF($A16>Settings!$B$15,"",C16-E16) -> 476669.62
A17: 3 | B17: =IF($A17>Settings!$B$15,"",EDATE(Settings!$B$16,$A17-1)) -> 46419 | C17: =IF($A17>Settings!$B$15,"",G16) -> 476669.62 | D17: =IF($A17>Settings!$B$15,"",C17*Settings!$B$14/12) -> 4766.6962 | E17: =IF($A17>Settings!$B$15,"",F17-D17) -> 11840.459 | F17: =IF($A17>Settings!$B$15,"",Settings!$B$17) -> 16607.155 | G17: =IF($A17>Settings!$B$15,"",C17-E17) -> 464829.16
A18: 4 | B18: =IF($A18>Settings!$B$15,"",EDATE(Settings!$B$16,$A18-1)) -> 46447 | C18: =IF($A18>Settings!$B$15,"",G17) -> 464829.16 | D18: =IF($A18>Settings!$B$15,"",C18*Settings!$B$14/12) -> 4648.2916 | E18: =IF($A18>Settings!$B$15,"",F18-D18) -> 11958.863 | F18: =IF($A18>Settings!$B$15,"",Settings!$B$17) -> 16607.155 | G18: =IF($A18>Settings!$B$15,"",C18-E18) -> 452870.3
A19: 5 | B19: =IF($A19>Settings!$B$15,"",EDATE(Settings!$B$16,$A19-1)) -> 46478 | C19: =IF($A19>Settings!$B$15,"",G18) -> 452870.3 | D19: =IF($A19>Settings!$B$15,"",C19*Settings!$B$14/12) -> 4528.703 | E19: =IF($A19>Settings!$B$15,"",F19-D19) -> 12078.452 | F19: =IF($A19>Settings!$B$15,"",Settings!$B$17) -> 16607.155 | G19: =IF($A19>Settings!$B$15,"",C19-E19) -> 440791.84
A20: 6 | B20: =IF($A20>Settings!$B$15,"",EDATE(Settings!$B$16,$A20-1)) -> 46508 | C20: =IF($A20>Settings!$B$15,"",G19) -> 440791.84 | D20: =IF($A20>Settings!$B$15,"",C20*Settings!$B$14/12) -> 4407.9184 | E20: =IF($A20>Settings!$B$15,"",F20-D20) -> 12199.236 | F20: =IF($A20>Settings!$B$15,"",Settings!$B$17) -> 16607.155 | G20: =IF($A20>Settings!$B$15,"",C20-E20) -> 428592.61
A21: 7 | B21: =IF($A21>Settings!$B$15,"",EDATE(Settings!$B$16,$A21-1)) -> 46539 | C21: =IF($A21>Settings!$B$15,"",G20) -> 428592.61 | D21: =IF($A21>Settings!$B$15,"",C21*Settings!$B$14/12) -> 4285.9261 | E21: =IF($A21>Settings!$B$15,"",F21-D21) -> 12321.229 | F21: =IF($A21>Settings!$B$15,"",Settings!$B$17) -> 16607.155 | G21: =IF($A21>Settings!$B$15,"",C21-E21) -> 416271.38
A22: 8 | B22: =IF($A22>Settings!$B$15,"",EDATE(Settings!$B$16,$A22-1)) -> 46569 | C22: =IF($A22>Settings!$B$15,"",G21) -> 416271.38 | D22: =IF($A22>Settings!$B$15,"",C22*Settings!$B$14/12) -> 4162.7138 | E22: =IF($A22>Settings!$B$15,"",F22-D22) -> 12444.441 | F22: =IF($A22>Settings!$B$15,"",Settings!$B$17) -> 16607.155 | G22: =IF($A22>Settings!$B$15,"",C22-E22) -> 403826.94
A23: 9 | B23: =IF($A23>Settings!$B$15,"",EDATE(Settings!$B$16,$A23-1)) -> 46600 | C23: =IF($A23>Settings!$B$15,"",G22) -> 403826.94 | D23: =IF($A23>Settings!$B$15,"",C23*Settings!$B$14/12) -> 4038.2694 | E23: =IF($A23>Settings!$B$15,"",F23-D23) -> 12568.886 | F23: =IF($A23>Settings!$B$15,"",Settings!$B$17) -> 16607.155 | G23: =IF($A23>Settings!$B$15,"",C23-E23) -> 391258.05
A24: 10 | B24: =IF($A24>Settings!$B$15,"",EDATE(Settings!$B$16,$A24-1)) -> 46631 | C24: =IF($A24>Settings!$B$15,"",G23) -> 391258.05 | D24: =IF($A24>Settings!$B$15,"",C24*Settings!$B$14/12) -> 3912.5805 | E24: =IF($A24>Settings!$B$15,"",F24-D24) -> 12694.574 | F24: =IF($A24>Settings!$B$15,"",Settings!$B$17) -> 16607.155 | G24: =IF($A24>Settings!$B$15,"",C24-E24) -> 378563.48
A25: 11 | B25: =IF($A25>Settings!$B$15,"",EDATE(Settings!$B$16,$A25-1)) -> 46661 | C25: =IF($A25>Settings!$B$15,"",G24) -> 378563.48 | D25: =IF($A25>Settings!$B$15,"",C25*Settings!$B$14/12) -> 3785.6348 | E25: =IF($A25>Settings!$B$15,"",F25-D25) -> 12821.52 | F25: =IF($A25>Settings!$B$15,"",Settings!$B$17) -> 16607.155 | G25: =IF($A25>Settings!$B$15,"",C25-E25) -> 365741.96
A26: 12 | B26: =IF($A26>Settings!$B$15,"",EDATE(Settings!$B$16,$A26-1)) -> 46692 | C26: =IF($A26>Settings!$B$15,"",G25) -> 365741.96 | D26: =IF($A26>Settings!$B$15,"",C26*Settings!$B$14/12) -> 3657.4196 | E26: =IF($A26>Settings!$B$15,"",F26-D26) -> 12949.735 | F26: =IF($A26>Settings!$B$15,"",Settings!$B$17) -> 16607.155 | G26: =IF($A26>Settings!$B$15,"",C26-E26) -> 352792.22
A27: 13 | B27: =IF($A27>Settings!$B$15,"",EDATE(Settings!$B$16,$A27-1)) -> 46722 | C27: =IF($A27>Settings!$B$15,"",G26) -> 352792.22 | D27: =IF($A27>Settings!$B$15,"",C27*Settings!$B$14/12) -> 3527.9222 | E27: =IF($A27>Settings!$B$15,"",F27-D27) -> 13079.233 | F27: =IF($A27>Settings!$B$15,"",Settings!$B$17) -> 16607.155 | G27: =IF($A27>Settings!$B$15,"",C27-E27) -> 339712.99
... A74: 60 | B74: =IF($A74>Settings!$B$15,"",EDATE(Settings!$B$16,$A74-1)) | C74: =IF($A74>Settings!$B$15,"",G73) | D74: =IF($A74>Settings!$B$15,"",C74*Settings!$B$14/12) | E74: =IF($A74>Settings!$B$15,"",F74-D74) | F74: =IF($A74>Settings!$B$15,"",Settings!$B$17) | G74: =IF($A74>Settings!$B$15,"",C74-E74)

Sheet Monthly Summary
A1: Monthly Summary
A2: Automatic. Months start from the 'First month to track' in Settings.
A5: Item | B5: =DATE(YEAR(Settings!B6),MONTH(Settings!B6),1) -> 46327 | C5: =EDATE(B5,1) -> 46357 | D5: =EDATE(C5,1) -> 46388 | E5: =EDATE(D5,1) -> 46419 | F5: =EDATE(E5,1) -> 46447 | G5: =EDATE(F5,1) -> 46478 | H5: =EDATE(G5,1) -> 46508 | I5: =EDATE(H5,1) -> 46539 | J5: =EDATE(I5,1) -> 46569 | ... M5: =EDATE(L5,1) -> 46661 | N5: Year total
A6: Sales
A7: Trading sessions logged | B7: =COUNTIFS('Daily Sales'!$A$6:$A$1005,">="&B$5,'Daily Sales'!$A$6:$A$1005,"<"&EDATE(B$5,1)) -> 4 | C7: =COUNTIFS('Daily Sales'!$A$6:$A$1005,">="&C$5,'Daily Sales'!$A$6:$A$1005,"<"&EDATE(C$5,1)) -> 0 | D7: =COUNTIFS('Daily Sales'!$A$6:$A$1005,">="&D$5,'Daily Sales'!$A$6:$A$1005,"<"&EDATE(D$5,1)) -> 0 | E7: =COUNTIFS('Daily Sales'!$A$6:$A$1005,">="&E$5,'Daily Sales'!$A$6:$A$1005,"<"&EDATE(E$5,1)) -> 0 | F7: =COUNTIFS('Daily Sales'!$A$6:$A$1005,">="&F$5,'Daily Sales'!$A$6:$A$1005,"<"&EDATE(F$5,1)) -> 0 | G7: =COUNTIFS('Daily Sales'!$A$6:$A$1005,">="&G$5,'Daily Sales'!$A$6:$A$1005,"<"&EDATE(G$5,1)) -> 0 | H7: =COUNTIFS('Daily Sales'!$A$6:$A$1005,">="&H$5,'Daily Sales'!$A$6:$A$1005,"<"&EDATE(H$5,1)) -> 0 | I7: =COUNTIFS('Daily Sales'!$A$6:$A$1005,">="&I$5,'Daily Sales'!$A$6:$A$1005,"<"&EDATE(I$5,1)) -> 0 | ... M7: =COUNTIFS('Daily Sales'!$A$6:$A$1005,">="&M$5,'Daily Sales'!$A$6:$A$1005,"<"&EDATE(M$5,1)) -> 0 | N7: =SUM(B7:M7) -> 4
A8: Units sold | B8: =SUMIFS('Daily Sales'!$K$6:$K$1005,'Daily Sales'!$A$6:$A$1005,">="&B$5,'Daily Sales'!$A$6:$A$1005,"<"&EDATE(B$5,1)) -> 167 | C8: =SUMIFS('Daily Sales'!$K$6:$K$1005,'Daily Sales'!$A$6:$A$1005,">="&C$5,'Daily Sales'!$A$6:$A$1005,"<"&EDATE(C$5,1)) -> 0 | D8: =SUMIFS('Daily Sales'!$K$6:$K$1005,'Daily Sales'!$A$6:$A$1005,">="&D$5,'Daily Sales'!$A$6:$A$1005,"<"&EDATE(D$5,1)) -> 0 | E8: =SUMIFS('Daily Sales'!$K$6:$K$1005,'Daily Sales'!$A$6:$A$1005,">="&E$5,'Daily Sales'!$A$6:$A$1005,"<"&EDATE(E$5,1)) -> 0 | F8: =SUMIFS('Daily Sales'!$K$6:$K$1005,'Daily Sales'!$A$6:$A$1005,">="&F$5,'Daily Sales'!$A$6:$A$1005,"<"&EDATE(F$5,1)) -> 0 | G8: =SUMIFS('Daily Sales'!$K$6:$K$1005,'Daily Sales'!$A$6:$A$1005,">="&G$5,'Daily Sales'!$A$6:$A$1005,"<"&EDATE(G$5,1)) -> 0 | H8: =SUMIFS('Daily Sales'!$K$6:$K$1005,'Daily Sales'!$A$6:$A$1005,">="&H$5,'Daily Sales'!$A$6:$A$1005,"<"&EDATE(H$5,1)) -> 0 | I8: =SUMIFS('Daily Sales'!$K$6:$K$1005,'Daily Sales'!$A$6:$A$1005,">="&I$5,'Daily Sales'!$A$6:$A$1005,"<"&EDATE(I$5,1)) -> 0 | ... M8: =SUMIFS('Daily Sales'!$K$6:$K$1005,'Daily Sales'!$A$6:$A$1005,">="&M$5,'Daily Sales'!$A$6:$A$1005,"<"&EDATE(M$5,1)) -> 0 | N8: =SUM(B8:M8) -> 167
A9: Free units given | B9: =SUMIFS('Daily Sales'!$E$6:$E$1005,'Daily Sales'!$A$6:$A$1005,">="&B$5,'Daily Sales'!$A$6:$A$1005,"<"&EDATE(B$5,1)) -> 4 | C9: =SUMIFS('Daily Sales'!$E$6:$E$1005,'Daily Sales'!$A$6:$A$1005,">="&C$5,'Daily Sales'!$A$6:$A$1005,"<"&EDATE(C$5,1)) -> 0 | D9: =SUMIFS('Daily Sales'!$E$6:$E$1005,'Daily Sales'!$A$6:$A$1005,">="&D$5,'Daily Sales'!$A$6:$A$1005,"<"&EDATE(D$5,1)) -> 0 | E9: =SUMIFS('Daily Sales'!$E$6:$E$1005,'Daily Sales'!$A$6:$A$1005,">="&E$5,'Daily Sales'!$A$6:$A$1005,"<"&EDATE(E$5,1)) -> 0 | F9: =SUMIFS('Daily Sales'!$E$6:$E$1005,'Daily Sales'!$A$6:$A$1005,">="&F$5,'Daily Sales'!$A$6:$A$1005,"<"&EDATE(F$5,1)) -> 0 | G9: =SUMIFS('Daily Sales'!$E$6:$E$1005,'Daily Sales'!$A$6:$A$1005,">="&G$5,'Daily Sales'!$A$6:$A$1005,"<"&EDATE(G$5,1)) -> 0 | H9: =SUMIFS('Daily Sales'!$E$6:$E$1005,'Daily Sales'!$A$6:$A$1005,">="&H$5,'Daily Sales'!$A$6:$A$1005,"<"&EDATE(H$5,1)) -> 0 | I9: =SUMIFS('Daily Sales'!$E$6:$E$1005,'Daily Sales'!$A$6:$A$1005,">="&I$5,'Daily Sales'!$A$6:$A$1005,"<"&EDATE(I$5,1)) -> 0 | ... M9: =SUMIFS('Daily Sales'!$E$6:$E$1005,'Daily Sales'!$A$6:$A$1005,">="&M$5,'Daily Sales'!$A$6:$A$1005,"<"&EDATE(M$5,1)) -> 0 | N9: =SUM(B9:M9) -> 4
A10: Revenue | B10: =SUMIFS('Daily Sales'!$L$6:$L$1005,'Daily Sales'!$A$6:$A$1005,">="&B$5,'Daily Sales'!$A$6:$A$1005,"<"&EDATE(B$5,1)) -> 90200 | C10: =SUMIFS('Daily Sales'!$L$6:$L$1005,'Daily Sales'!$A$6:$A$1005,">="&C$5,'Daily Sales'!$A$6:$A$1005,"<"&EDATE(C$5,1)) -> 0 | D10: =SUMIFS('Daily Sales'!$L$6:$L$1005,'Daily Sales'!$A$6:$A$1005,">="&D$5,'Daily Sales'!$A$6:$A$1005,"<"&EDATE(D$5,1)) -> 0 | E10: =SUMIFS('Daily Sales'!$L$6:$L$1005,'Daily Sales'!$A$6:$A$1005,">="&E$5,'Daily Sales'!$A$6:$A$1005,"<"&EDATE(E$5,1)) -> 0 | F10: =SUMIFS('Daily Sales'!$L$6:$L$1005,'Daily Sales'!$A$6:$A$1005,">="&F$5,'Daily Sales'!$A$6:$A$1005,"<"&EDATE(F$5,1)) -> 0 | G10: =SUMIFS('Daily Sales'!$L$6:$L$1005,'Daily Sales'!$A$6:$A$1005,">="&G$5,'Daily Sales'!$A$6:$A$1005,"<"&EDATE(G$5,1)) -> 0 | H10: =SUMIFS('Daily Sales'!$L$6:$L$1005,'Daily Sales'!$A$6:$A$1005,">="&H$5,'Daily Sales'!$A$6:$A$1005,"<"&EDATE(H$5,1)) -> 0 | I10: =SUMIFS('Daily Sales'!$L$6:$L$1005,'Daily Sales'!$A$6:$A$1005,">="&I$5,'Daily Sales'!$A$6:$A$1005,"<"&EDATE(I$5,1)) -> 0 | ... M10: =SUMIFS('Daily Sales'!$L$6:$L$1005,'Daily Sales'!$A$6:$A$1005,">="&M$5,'Daily Sales'!$A$6:$A$1005,"<"&EDATE(M$5,1)) -> 0 | N10: =SUM(B10:M10) -> 90200
A11: Less: venue share | B11: =SUMIFS('Daily Sales'!$M$6:$M$1005,'Daily Sales'!$A$6:$A$1005,">="&B$5,'Daily Sales'!$A$6:$A$1005,"<"&EDATE(B$5,1)) -> 9020 | C11: =SUMIFS('Daily Sales'!$M$6:$M$1005,'Daily Sales'!$A$6:$A$1005,">="&C$5,'Daily Sales'!$A$6:$A$1005,"<"&EDATE(C$5,1)) -> 0 | D11: =SUMIFS('Daily Sales'!$M$6:$M$1005,'Daily Sales'!$A$6:$A$1005,">="&D$5,'Daily Sales'!$A$6:$A$1005,"<"&EDATE(D$5,1)) -> 0 | E11: =SUMIFS('Daily Sales'!$M$6:$M$1005,'Daily Sales'!$A$6:$A$1005,">="&E$5,'Daily Sales'!$A$6:$A$1005,"<"&EDATE(E$5,1)) -> 0 | F11: =SUMIFS('Daily Sales'!$M$6:$M$1005,'Daily Sales'!$A$6:$A$1005,">="&F$5,'Daily Sales'!$A$6:$A$1005,"<"&EDATE(F$5,1)) -> 0 | G11: =SUMIFS('Daily Sales'!$M$6:$M$1005,'Daily Sales'!$A$6:$A$1005,">="&G$5,'Daily Sales'!$A$6:$A$1005,"<"&EDATE(G$5,1)) -> 0 | H11: =SUMIFS('Daily Sales'!$M$6:$M$1005,'Daily Sales'!$A$6:$A$1005,">="&H$5,'Daily Sales'!$A$6:$A$1005,"<"&EDATE(H$5,1)) -> 0 | I11: =SUMIFS('Daily Sales'!$M$6:$M$1005,'Daily Sales'!$A$6:$A$1005,">="&I$5,'Daily Sales'!$A$6:$A$1005,"<"&EDATE(I$5,1)) -> 0 | ... M11: =SUMIFS('Daily Sales'!$M$6:$M$1005,'Daily Sales'!$A$6:$A$1005,">="&M$5,'Daily Sales'!$A$6:$A$1005,"<"&EDATE(M$5,1)) -> 0 | N11: =SUM(B11:M11) -> 9020
A12: Net sales after venue share | B12: =B10-B11 -> 81180 | C12: =C10-C11 -> 0 | D12: =D10-D11 -> 0 | E12: =E10-E11 -> 0 | F12: =F10-F11 -> 0 | G12: =G10-G11 -> 0 | H12: =H10-H11 -> 0 | I12: =I10-I11 -> 0 | ... N12: =N10-N11 -> 81180
A13: Operating expenses
A14: =Settings!A41 -> Ingredients | B14: =SUMIFS(Expenses!$D$6:$D$2005,Expenses!$B$6:$B$2005,$A14,Expenses!$A$6:$A$2005,">="&B$5,Expenses!$A$6:$A$2005,"<"&EDATE(B$5,1)) -> 0 | C14: =SUMIFS(Expenses!$D$6:$D$2005,Expenses!$B$6:$B$2005,$A14,Expenses!$A$6:$A$2005,">="&C$5,Expenses!$A$6:$A$2005,"<"&EDATE(C$5,1)) -> 0 | D14: =SUMIFS(Expenses!$D$6:$D$2005,Expenses!$B$6:$B$2005,$A14,Expenses!$A$6:$A$2005,">="&D$5,Expenses!$A$6:$A$2005,"<"&EDATE(D$5,1)) -> 0 | E14: =SUMIFS(Expenses!$D$6:$D$2005,Expenses!$B$6:$B$2005,$A14,Expenses!$A$6:$A$2005,">="&E$5,Expenses!$A$6:$A$2005,"<"&EDATE(E$5,1)) -> 0 | F14: =SUMIFS(Expenses!$D$6:$D$2005,Expenses!$B$6:$B$2005,$A14,Expenses!$A$6:$A$2005,">="&F$5,Expenses!$A$6:$A$2005,"<"&EDATE(F$5,1)) -> 0 | G14: =SUMIFS(Expenses!$D$6:$D$2005,Expenses!$B$6:$B$2005,$A14,Expenses!$A$6:$A$2005,">="&G$5,Expenses!$A$6:$A$2005,"<"&EDATE(G$5,1)) -> 0 | H14: =SUMIFS(Expenses!$D$6:$D$2005,Expenses!$B$6:$B$2005,$A14,Expenses!$A$6:$A$2005,">="&H$5,Expenses!$A$6:$A$2005,"<"&EDATE(H$5,1)) -> 0 | I14: =SUMIFS(Expenses!$D$6:$D$2005,Expenses!$B$6:$B$2005,$A14,Expenses!$A$6:$A$2005,">="&I$5,Expenses!$A$6:$A$2005,"<"&EDATE(I$5,1)) -> 0 | ... M14: =SUMIFS(Expenses!$D$6:$D$2005,Expenses!$B$6:$B$2005,$A14,Expenses!$A$6:$A$2005,">="&M$5,Expenses!$A$6:$A$2005,"<"&EDATE(M$5,1)) -> 0 | N14: =SUM(B14:M14) -> 0
A15: =Settings!A42 -> Packaging | B15: =SUMIFS(Expenses!$D$6:$D$2005,Expenses!$B$6:$B$2005,$A15,Expenses!$A$6:$A$2005,">="&B$5,Expenses!$A$6:$A$2005,"<"&EDATE(B$5,1)) -> 0 | C15: =SUMIFS(Expenses!$D$6:$D$2005,Expenses!$B$6:$B$2005,$A15,Expenses!$A$6:$A$2005,">="&C$5,Expenses!$A$6:$A$2005,"<"&EDATE(C$5,1)) -> 0 | D15: =SUMIFS(Expenses!$D$6:$D$2005,Expenses!$B$6:$B$2005,$A15,Expenses!$A$6:$A$2005,">="&D$5,Expenses!$A$6:$A$2005,"<"&EDATE(D$5,1)) -> 0 | E15: =SUMIFS(Expenses!$D$6:$D$2005,Expenses!$B$6:$B$2005,$A15,Expenses!$A$6:$A$2005,">="&E$5,Expenses!$A$6:$A$2005,"<"&EDATE(E$5,1)) -> 0 | F15: =SUMIFS(Expenses!$D$6:$D$2005,Expenses!$B$6:$B$2005,$A15,Expenses!$A$6:$A$2005,">="&F$5,Expenses!$A$6:$A$2005,"<"&EDATE(F$5,1)) -> 0 | G15: =SUMIFS(Expenses!$D$6:$D$2005,Expenses!$B$6:$B$2005,$A15,Expenses!$A$6:$A$2005,">="&G$5,Expenses!$A$6:$A$2005,"<"&EDATE(G$5,1)) -> 0 | H15: =SUMIFS(Expenses!$D$6:$D$2005,Expenses!$B$6:$B$2005,$A15,Expenses!$A$6:$A$2005,">="&H$5,Expenses!$A$6:$A$2005,"<"&EDATE(H$5,1)) -> 0 | I15: =SUMIFS(Expenses!$D$6:$D$2005,Expenses!$B$6:$B$2005,$A15,Expenses!$A$6:$A$2005,">="&I$5,Expenses!$A$6:$A$2005,"<"&EDATE(I$5,1)) -> 0 | ... M15: =SUMIFS(Expenses!$D$6:$D$2005,Expenses!$B$6:$B$2005,$A15,Expenses!$A$6:$A$2005,">="&M$5,Expenses!$A$6:$A$2005,"<"&EDATE(M$5,1)) -> 0 | N15: =SUM(B15:M15) -> 0
A16: =Settings!A43 -> Staff pay | B16: =SUMIFS(Expenses!$D$6:$D$2005,Expenses!$B$6:$B$2005,$A16,Expenses!$A$6:$A$2005,">="&B$5,Expenses!$A$6:$A$2005,"<"&EDATE(B$5,1)) -> 0 | C16: =SUMIFS(Expenses!$D$6:$D$2005,Expenses!$B$6:$B$2005,$A16,Expenses!$A$6:$A$2005,">="&C$5,Expenses!$A$6:$A$2005,"<"&EDATE(C$5,1)) -> 0 | D16: =SUMIFS(Expenses!$D$6:$D$2005,Expenses!$B$6:$B$2005,$A16,Expenses!$A$6:$A$2005,">="&D$5,Expenses!$A$6:$A$2005,"<"&EDATE(D$5,1)) -> 0 | E16: =SUMIFS(Expenses!$D$6:$D$2005,Expenses!$B$6:$B$2005,$A16,Expenses!$A$6:$A$2005,">="&E$5,Expenses!$A$6:$A$2005,"<"&EDATE(E$5,1)) -> 0 | F16: =SUMIFS(Expenses!$D$6:$D$2005,Expenses!$B$6:$B$2005,$A16,Expenses!$A$6:$A$2005,">="&F$5,Expenses!$A$6:$A$2005,"<"&EDATE(F$5,1)) -> 0 | G16: =SUMIFS(Expenses!$D$6:$D$2005,Expenses!$B$6:$B$2005,$A16,Expenses!$A$6:$A$2005,">="&G$5,Expenses!$A$6:$A$2005,"<"&EDATE(G$5,1)) -> 0 | H16: =SUMIFS(Expenses!$D$6:$D$2005,Expenses!$B$6:$B$2005,$A16,Expenses!$A$6:$A$2005,">="&H$5,Expenses!$A$6:$A$2005,"<"&EDATE(H$5,1)) -> 0 | I16: =SUMIFS(Expenses!$D$6:$D$2005,Expenses!$B$6:$B$2005,$A16,Expenses!$A$6:$A$2005,">="&I$5,Expenses!$A$6:$A$2005,"<"&EDATE(I$5,1)) -> 0 | ... M16: =SUMIFS(Expenses!$D$6:$D$2005,Expenses!$B$6:$B$2005,$A16,Expenses!$A$6:$A$2005,">="&M$5,Expenses!$A$6:$A$2005,"<"&EDATE(M$5,1)) -> 0 | N16: =SUM(B16:M16) -> 0
A17: =Settings!A44 -> Utilities | B17: =SUMIFS(Expenses!$D$6:$D$2005,Expenses!$B$6:$B$2005,$A17,Expenses!$A$6:$A$2005,">="&B$5,Expenses!$A$6:$A$2005,"<"&EDATE(B$5,1)) -> 0 | C17: =SUMIFS(Expenses!$D$6:$D$2005,Expenses!$B$6:$B$2005,$A17,Expenses!$A$6:$A$2005,">="&C$5,Expenses!$A$6:$A$2005,"<"&EDATE(C$5,1)) -> 0 | D17: =SUMIFS(Expenses!$D$6:$D$2005,Expenses!$B$6:$B$2005,$A17,Expenses!$A$6:$A$2005,">="&D$5,Expenses!$A$6:$A$2005,"<"&EDATE(D$5,1)) -> 0 | E17: =SUMIFS(Expenses!$D$6:$D$2005,Expenses!$B$6:$B$2005,$A17,Expenses!$A$6:$A$2005,">="&E$5,Expenses!$A$6:$A$2005,"<"&EDATE(E$5,1)) -> 0 | F17: =SUMIFS(Expenses!$D$6:$D$2005,Expenses!$B$6:$B$2005,$A17,Expenses!$A$6:$A$2005,">="&F$5,Expenses!$A$6:$A$2005,"<"&EDATE(F$5,1)) -> 0 | G17: =SUMIFS(Expenses!$D$6:$D$2005,Expenses!$B$6:$B$2005,$A17,Expenses!$A$6:$A$2005,">="&G$5,Expenses!$A$6:$A$2005,"<"&EDATE(G$5,1)) -> 0 | H17: =SUMIFS(Expenses!$D$6:$D$2005,Expenses!$B$6:$B$2005,$A17,Expenses!$A$6:$A$2005,">="&H$5,Expenses!$A$6:$A$2005,"<"&EDATE(H$5,1)) -> 0 | I17: =SUMIFS(Expenses!$D$6:$D$2005,Expenses!$B$6:$B$2005,$A17,Expenses!$A$6:$A$2005,">="&I$5,Expenses!$A$6:$A$2005,"<"&EDATE(I$5,1)) -> 0 | ... M17: =SUMIFS(Expenses!$D$6:$D$2005,Expenses!$B$6:$B$2005,$A17,Expenses!$A$6:$A$2005,">="&M$5,Expenses!$A$6:$A$2005,"<"&EDATE(M$5,1)) -> 0 | N17: =SUM(B17:M17) -> 0
A18: =Settings!A45 -> Marketing | B18: =SUMIFS(Expenses!$D$6:$D$2005,Expenses!$B$6:$B$2005,$A18,Expenses!$A$6:$A$2005,">="&B$5,Expenses!$A$6:$A$2005,"<"&EDATE(B$5,1)) -> 0 | C18: =SUMIFS(Expenses!$D$6:$D$2005,Expenses!$B$6:$B$2005,$A18,Expenses!$A$6:$A$2005,">="&C$5,Expenses!$A$6:$A$2005,"<"&EDATE(C$5,1)) -> 0 | D18: =SUMIFS(Expenses!$D$6:$D$2005,Expenses!$B$6:$B$2005,$A18,Expenses!$A$6:$A$2005,">="&D$5,Expenses!$A$6:$A$2005,"<"&EDATE(D$5,1)) -> 0 | E18: =SUMIFS(Expenses!$D$6:$D$2005,Expenses!$B$6:$B$2005,$A18,Expenses!$A$6:$A$2005,">="&E$5,Expenses!$A$6:$A$2005,"<"&EDATE(E$5,1)) -> 0 | F18: =SUMIFS(Expenses!$D$6:$D$2005,Expenses!$B$6:$B$2005,$A18,Expenses!$A$6:$A$2005,">="&F$5,Expenses!$A$6:$A$2005,"<"&EDATE(F$5,1)) -> 0 | G18: =SUMIFS(Expenses!$D$6:$D$2005,Expenses!$B$6:$B$2005,$A18,Expenses!$A$6:$A$2005,">="&G$5,Expenses!$A$6:$A$2005,"<"&EDATE(G$5,1)) -> 0 | H18: =SUMIFS(Expenses!$D$6:$D$2005,Expenses!$B$6:$B$2005,$A18,Expenses!$A$6:$A$2005,">="&H$5,Expenses!$A$6:$A$2005,"<"&EDATE(H$5,1)) -> 0 | I18: =SUMIFS(Expenses!$D$6:$D$2005,Expenses!$B$6:$B$2005,$A18,Expenses!$A$6:$A$2005,">="&I$5,Expenses!$A$6:$A$2005,"<"&EDATE(I$5,1)) -> 0 | ... M18: =SUMIFS(Expenses!$D$6:$D$2005,Expenses!$B$6:$B$2005,$A18,Expenses!$A$6:$A$2005,">="&M$5,Expenses!$A$6:$A$2005,"<"&EDATE(M$5,1)) -> 0 | N18: =SUM(B18:M18) -> 0
A19: =Settings!A46 -> Transport | B19: =SUMIFS(Expenses!$D$6:$D$2005,Expenses!$B$6:$B$2005,$A19,Expenses!$A$6:$A$2005,">="&B$5,Expenses!$A$6:$A$2005,"<"&EDATE(B$5,1)) -> 0 | C19: =SUMIFS(Expenses!$D$6:$D$2005,Expenses!$B$6:$B$2005,$A19,Expenses!$A$6:$A$2005,">="&C$5,Expenses!$A$6:$A$2005,"<"&EDATE(C$5,1)) -> 0 | D19: =SUMIFS(Expenses!$D$6:$D$2005,Expenses!$B$6:$B$2005,$A19,Expenses!$A$6:$A$2005,">="&D$5,Expenses!$A$6:$A$2005,"<"&EDATE(D$5,1)) -> 0 | E19: =SUMIFS(Expenses!$D$6:$D$2005,Expenses!$B$6:$B$2005,$A19,Expenses!$A$6:$A$2005,">="&E$5,Expenses!$A$6:$A$2005,"<"&EDATE(E$5,1)) -> 0 | F19: =SUMIFS(Expenses!$D$6:$D$2005,Expenses!$B$6:$B$2005,$A19,Expenses!$A$6:$A$2005,">="&F$5,Expenses!$A$6:$A$2005,"<"&EDATE(F$5,1)) -> 0 | G19: =SUMIFS(Expenses!$D$6:$D$2005,Expenses!$B$6:$B$2005,$A19,Expenses!$A$6:$A$2005,">="&G$5,Expenses!$A$6:$A$2005,"<"&EDATE(G$5,1)) -> 0 | H19: =SUMIFS(Expenses!$D$6:$D$2005,Expenses!$B$6:$B$2005,$A19,Expenses!$A$6:$A$2005,">="&H$5,Expenses!$A$6:$A$2005,"<"&EDATE(H$5,1)) -> 0 | I19: =SUMIFS(Expenses!$D$6:$D$2005,Expenses!$B$6:$B$2005,$A19,Expenses!$A$6:$A$2005,">="&I$5,Expenses!$A$6:$A$2005,"<"&EDATE(I$5,1)) -> 0 | ... M19: =SUMIFS(Expenses!$D$6:$D$2005,Expenses!$B$6:$B$2005,$A19,Expenses!$A$6:$A$2005,">="&M$5,Expenses!$A$6:$A$2005,"<"&EDATE(M$5,1)) -> 0 | N19: =SUM(B19:M19) -> 0
A20: =Settings!A47 -> Repairs and supplies | B20: =SUMIFS(Expenses!$D$6:$D$2005,Expenses!$B$6:$B$2005,$A20,Expenses!$A$6:$A$2005,">="&B$5,Expenses!$A$6:$A$2005,"<"&EDATE(B$5,1)) -> 0 | C20: =SUMIFS(Expenses!$D$6:$D$2005,Expenses!$B$6:$B$2005,$A20,Expenses!$A$6:$A$2005,">="&C$5,Expenses!$A$6:$A$2005,"<"&EDATE(C$5,1)) -> 0 | D20: =SUMIFS(Expenses!$D$6:$D$2005,Expenses!$B$6:$B$2005,$A20,Expenses!$A$6:$A$2005,">="&D$5,Expenses!$A$6:$A$2005,"<"&EDATE(D$5,1)) -> 0 | E20: =SUMIFS(Expenses!$D$6:$D$2005,Expenses!$B$6:$B$2005,$A20,Expenses!$A$6:$A$2005,">="&E$5,Expenses!$A$6:$A$2005,"<"&EDATE(E$5,1)) -> 0 | F20: =SUMIFS(Expenses!$D$6:$D$2005,Expenses!$B$6:$B$2005,$A20,Expenses!$A$6:$A$2005,">="&F$5,Expenses!$A$6:$A$2005,"<"&EDATE(F$5,1)) -> 0 | G20: =SUMIFS(Expenses!$D$6:$D$2005,Expenses!$B$6:$B$2005,$A20,Expenses!$A$6:$A$2005,">="&G$5,Expenses!$A$6:$A$2005,"<"&EDATE(G$5,1)) -> 0 | H20: =SUMIFS(Expenses!$D$6:$D$2005,Expenses!$B$6:$B$2005,$A20,Expenses!$A$6:$A$2005,">="&H$5,Expenses!$A$6:$A$2005,"<"&EDATE(H$5,1)) -> 0 | I20: =SUMIFS(Expenses!$D$6:$D$2005,Expenses!$B$6:$B$2005,$A20,Expenses!$A$6:$A$2005,">="&I$5,Expenses!$A$6:$A$2005,"<"&EDATE(I$5,1)) -> 0 | ... M20: =SUMIFS(Expenses!$D$6:$D$2005,Expenses!$B$6:$B$2005,$A20,Expenses!$A$6:$A$2005,">="&M$5,Expenses!$A$6:$A$2005,"<"&EDATE(M$5,1)) -> 0 | N20: =SUM(B20:M20) -> 0
A21: =Settings!A48 -> Permits and registration | B21: =SUMIFS(Expenses!$D$6:$D$2005,Expenses!$B$6:$B$2005,$A21,Expenses!$A$6:$A$2005,">="&B$5,Expenses!$A$6:$A$2005,"<"&EDATE(B$5,1)) -> 0 | C21: =SUMIFS(Expenses!$D$6:$D$2005,Expenses!$B$6:$B$2005,$A21,Expenses!$A$6:$A$2005,">="&C$5,Expenses!$A$6:$A$2005,"<"&EDATE(C$5,1)) -> 0 | D21: =SUMIFS(Expenses!$D$6:$D$2005,Expenses!$B$6:$B$2005,$A21,Expenses!$A$6:$A$2005,">="&D$5,Expenses!$A$6:$A$2005,"<"&EDATE(D$5,1)) -> 0 | E21: =SUMIFS(Expenses!$D$6:$D$2005,Expenses!$B$6:$B$2005,$A21,Expenses!$A$6:$A$2005,">="&E$5,Expenses!$A$6:$A$2005,"<"&EDATE(E$5,1)) -> 0 | F21: =SUMIFS(Expenses!$D$6:$D$2005,Expenses!$B$6:$B$2005,$A21,Expenses!$A$6:$A$2005,">="&F$5,Expenses!$A$6:$A$2005,"<"&EDATE(F$5,1)) -> 0 | G21: =SUMIFS(Expenses!$D$6:$D$2005,Expenses!$B$6:$B$2005,$A21,Expenses!$A$6:$A$2005,">="&G$5,Expenses!$A$6:$A$2005,"<"&EDATE(G$5,1)) -> 0 | H21: =SUMIFS(Expenses!$D$6:$D$2005,Expenses!$B$6:$B$2005,$A21,Expenses!$A$6:$A$2005,">="&H$5,Expenses!$A$6:$A$2005,"<"&EDATE(H$5,1)) -> 0 | I21: =SUMIFS(Expenses!$D$6:$D$2005,Expenses!$B$6:$B$2005,$A21,Expenses!$A$6:$A$2005,">="&I$5,Expenses!$A$6:$A$2005,"<"&EDATE(I$5,1)) -> 0 | ... M21: =SUMIFS(Expenses!$D$6:$D$2005,Expenses!$B$6:$B$2005,$A21,Expenses!$A$6:$A$2005,">="&M$5,Expenses!$A$6:$A$2005,"<"&EDATE(M$5,1)) -> 0 | N21: =SUM(B21:M21) -> 0
A22: =Settings!A49 -> Other operating | B22: =SUMIFS(Expenses!$D$6:$D$2005,Expenses!$B$6:$B$2005,$A22,Expenses!$A$6:$A$2005,">="&B$5,Expenses!$A$6:$A$2005,"<"&EDATE(B$5,1)) -> 0 | C22: =SUMIFS(Expenses!$D$6:$D$2005,Expenses!$B$6:$B$2005,$A22,Expenses!$A$6:$A$2005,">="&C$5,Expenses!$A$6:$A$2005,"<"&EDATE(C$5,1)) -> 0 | D22: =SUMIFS(Expenses!$D$6:$D$2005,Expenses!$B$6:$B$2005,$A22,Expenses!$A$6:$A$2005,">="&D$5,Expenses!$A$6:$A$2005,"<"&EDATE(D$5,1)) -> 0 | E22: =SUMIFS(Expenses!$D$6:$D$2005,Expenses!$B$6:$B$2005,$A22,Expenses!$A$6:$A$2005,">="&E$5,Expenses!$A$6:$A$2005,"<"&EDATE(E$5,1)) -> 0 | F22: =SUMIFS(Expenses!$D$6:$D$2005,Expenses!$B$6:$B$2005,$A22,Expenses!$A$6:$A$2005,">="&F$5,Expenses!$A$6:$A$2005,"<"&EDATE(F$5,1)) -> 0 | G22: =SUMIFS(Expenses!$D$6:$D$2005,Expenses!$B$6:$B$2005,$A22,Expenses!$A$6:$A$2005,">="&G$5,Expenses!$A$6:$A$2005,"<"&EDATE(G$5,1)) -> 0 | H22: =SUMIFS(Expenses!$D$6:$D$2005,Expenses!$B$6:$B$2005,$A22,Expenses!$A$6:$A$2005,">="&H$5,Expenses!$A$6:$A$2005,"<"&EDATE(H$5,1)) -> 0 | I22: =SUMIFS(Expenses!$D$6:$D$2005,Expenses!$B$6:$B$2005,$A22,Expenses!$A$6:$A$2005,">="&I$5,Expenses!$A$6:$A$2005,"<"&EDATE(I$5,1)) -> 0 | ... M22: =SUMIFS(Expenses!$D$6:$D$2005,Expenses!$B$6:$B$2005,$A22,Expenses!$A$6:$A$2005,">="&M$5,Expenses!$A$6:$A$2005,"<"&EDATE(M$5,1)) -> 0 | N22: =SUM(B22:M22) -> 0
A23: Other operating categories you added | B23: =B24-SUM(B14:B22) -> 0 | C23: =C24-SUM(C14:C22) -> 0 | D23: =D24-SUM(D14:D22) -> 0 | E23: =E24-SUM(E14:E22) -> 0 | F23: =F24-SUM(F14:F22) -> 0 | G23: =G24-SUM(G14:G22) -> 0 | H23: =H24-SUM(H14:H22) -> 0 | I23: =I24-SUM(I14:I22) -> 0 | ... N23: =N24-SUM(N14:N22) -> 0
A24: Total operating expenses | B24: =SUMIFS(Expenses!$D$6:$D$2005,Expenses!$G$6:$G$2005,"Operating",Expenses!$A$6:$A$2005,">="&B$5,Expenses!$A$6:$A$2005,"<"&EDATE(B$5,1)) -> 0 | C24: =SUMIFS(Expenses!$D$6:$D$2005,Expenses!$G$6:$G$2005,"Operating",Expenses!$A$6:$A$2005,">="&C$5,Expenses!$A$6:$A$2005,"<"&EDATE(C$5,1)) -> 0 | D24: =SUMIFS(Expenses!$D$6:$D$2005,Expenses!$G$6:$G$2005,"Operating",Expenses!$A$6:$A$2005,">="&D$5,Expenses!$A$6:$A$2005,"<"&EDATE(D$5,1)) -> 0 | E24: =SUMIFS(Expenses!$D$6:$D$2005,Expenses!$G$6:$G$2005,"Operating",Expenses!$A$6:$A$2005,">="&E$5,Expenses!$A$6:$A$2005,"<"&EDATE(E$5,1)) -> 0 | F24: =SUMIFS(Expenses!$D$6:$D$2005,Expenses!$G$6:$G$2005,"Operating",Expenses!$A$6:$A$2005,">="&F$5,Expenses!$A$6:$A$2005,"<"&EDATE(F$5,1)) -> 0 | G24: =SUMIFS(Expenses!$D$6:$D$2005,Expenses!$G$6:$G$2005,"Operating",Expenses!$A$6:$A$2005,">="&G$5,Expenses!$A$6:$A$2005,"<"&EDATE(G$5,1)) -> 0 | H24: =SUMIFS(Expenses!$D$6:$D$2005,Expenses!$G$6:$G$2005,"Operating",Expenses!$A$6:$A$2005,">="&H$5,Expenses!$A$6:$A$2005,"<"&EDATE(H$5,1)) -> 0 | I24: =SUMIFS(Expenses!$D$6:$D$2005,Expenses!$G$6:$G$2005,"Operating",Expenses!$A$6:$A$2005,">="&I$5,Expenses!$A$6:$A$2005,"<"&EDATE(I$5,1)) -> 0 | ... M24: =SUMIFS(Expenses!$D$6:$D$2005,Expenses!$G$6:$G$2005,"Operating",Expenses!$A$6:$A$2005,">="&M$5,Expenses!$A$6:$A$2005,"<"&EDATE(M$5,1)) -> 0 | N24: =SUM(B24:M24) -> 0
A25: Profit
A26: Operating profit | B26: =B12-B24 -> 81180 | C26: =C12-C24 -> 0 | D26: =D12-D24 -> 0 | E26: =E12-E24 -> 0 | F26: =F12-F24 -> 0 | G26: =G12-G24 -> 0 | H26: =H12-H24 -> 0 | I26: =I12-I24 -> 0 | ... N26: =N12-N24 -> 81180
A27: Loan installments paid | B27: =SUMIFS(Expenses!$D$6:$D$2005,Expenses!$G$6:$G$2005,"Loan",Expenses!$A$6:$A$2005,">="&B$5,Expenses!$A$6:$A$2005,"<"&EDATE(B$5,1)) -> 0 | C27: =SUMIFS(Expenses!$D$6:$D$2005,Expenses!$G$6:$G$2005,"Loan",Expenses!$A$6:$A$2005,">="&C$5,Expenses!$A$6:$A$2005,"<"&EDATE(C$5,1)) -> 0 | D27: =SUMIFS(Expenses!$D$6:$D$2005,Expenses!$G$6:$G$2005,"Loan",Expenses!$A$6:$A$2005,">="&D$5,Expenses!$A$6:$A$2005,"<"&EDATE(D$5,1)) -> 0 | E27: =SUMIFS(Expenses!$D$6:$D$2005,Expenses!$G$6:$G$2005,"Loan",Expenses!$A$6:$A$2005,">="&E$5,Expenses!$A$6:$A$2005,"<"&EDATE(E$5,1)) -> 0 | F27: =SUMIFS(Expenses!$D$6:$D$2005,Expenses!$G$6:$G$2005,"Loan",Expenses!$A$6:$A$2005,">="&F$5,Expenses!$A$6:$A$2005,"<"&EDATE(F$5,1)) -> 0 | G27: =SUMIFS(Expenses!$D$6:$D$2005,Expenses!$G$6:$G$2005,"Loan",Expenses!$A$6:$A$2005,">="&G$5,Expenses!$A$6:$A$2005,"<"&EDATE(G$5,1)) -> 0 | H27: =SUMIFS(Expenses!$D$6:$D$2005,Expenses!$G$6:$G$2005,"Loan",Expenses!$A$6:$A$2005,">="&H$5,Expenses!$A$6:$A$2005,"<"&EDATE(H$5,1)) -> 0 | I27: =SUMIFS(Expenses!$D$6:$D$2005,Expenses!$G$6:$G$2005,"Loan",Expenses!$A$6:$A$2005,">="&I$5,Expenses!$A$6:$A$2005,"<"&EDATE(I$5,1)) -> 0 | ... M27: =SUMIFS(Expenses!$D$6:$D$2005,Expenses!$G$6:$G$2005,"Loan",Expenses!$A$6:$A$2005,">="&M$5,Expenses!$A$6:$A$2005,"<"&EDATE(M$5,1)) -> 0 | N27: =SUM(B27:M27) -> 0
A28: Net profit after loan | B28: =B26-B27 -> 81180 | C28: =C26-C27 -> 0 | D28: =D26-D27 -> 0 | E28: =E26-E27 -> 0 | F28: =F26-F27 -> 0 | G28: =G26-G27 -> 0 | H28: =H26-H27 -> 0 | I28: =I26-I27 -> 0 | ... N28: =N26-N27 -> 81180
A29: Net margin (net profit / revenue) | B29: =IF(B10=0,0,B28/B10) -> 0.9 | C29: =IF(C10=0,0,C28/C10) -> 0 | D29: =IF(D10=0,0,D28/D10) -> 0 | E29: =IF(E10=0,0,E28/E10) -> 0 | F29: =IF(F10=0,0,F28/F10) -> 0 | G29: =IF(G10=0,0,G28/G10) -> 0 | H29: =IF(H10=0,0,H28/H10) -> 0 | I29: =IF(I10=0,0,I28/I10) -> 0 | ... N29: =IF(N10=0,0,N28/N10) -> 0.9
A30: Money movements (not part of profit)
A31: Startup / capital spending | B31: =SUMIFS(Expenses!$D$6:$D$2005,Expenses!$G$6:$G$2005,"Capital",Expenses!$A$6:$A$2005,">="&B$5,Expenses!$A$6:$A$2005,"<"&EDATE(B$5,1)) -> 0 | C31: =SUMIFS(Expenses!$D$6:$D$2005,Expenses!$G$6:$G$2005,"Capital",Expenses!$A$6:$A$2005,">="&C$5,Expenses!$A$6:$A$2005,"<"&EDATE(C$5,1)) -> 0 | D31: =SUMIFS(Expenses!$D$6:$D$2005,Expenses!$G$6:$G$2005,"Capital",Expenses!$A$6:$A$2005,">="&D$5,Expenses!$A$6:$A$2005,"<"&EDATE(D$5,1)) -> 0 | E31: =SUMIFS(Expenses!$D$6:$D$2005,Expenses!$G$6:$G$2005,"Capital",Expenses!$A$6:$A$2005,">="&E$5,Expenses!$A$6:$A$2005,"<"&EDATE(E$5,1)) -> 0 | F31: =SUMIFS(Expenses!$D$6:$D$2005,Expenses!$G$6:$G$2005,"Capital",Expenses!$A$6:$A$2005,">="&F$5,Expenses!$A$6:$A$2005,"<"&EDATE(F$5,1)) -> 0 | G31: =SUMIFS(Expenses!$D$6:$D$2005,Expenses!$G$6:$G$2005,"Capital",Expenses!$A$6:$A$2005,">="&G$5,Expenses!$A$6:$A$2005,"<"&EDATE(G$5,1)) -> 0 | H31: =SUMIFS(Expenses!$D$6:$D$2005,Expenses!$G$6:$G$2005,"Capital",Expenses!$A$6:$A$2005,">="&H$5,Expenses!$A$6:$A$2005,"<"&EDATE(H$5,1)) -> 0 | I31: =SUMIFS(Expenses!$D$6:$D$2005,Expenses!$G$6:$G$2005,"Capital",Expenses!$A$6:$A$2005,">="&I$5,Expenses!$A$6:$A$2005,"<"&EDATE(I$5,1)) -> 0 | ... M31: =SUMIFS(Expenses!$D$6:$D$2005,Expenses!$G$6:$G$2005,"Capital",Expenses!$A$6:$A$2005,">="&M$5,Expenses!$A$6:$A$2005,"<"&EDATE(M$5,1)) -> 0 | N31: =SUM(B31:M31) -> 0
A32: Owner withdrawals | B32: =SUMIFS(Expenses!$D$6:$D$2005,Expenses!$G$6:$G$2005,"Owner",Expenses!$A$6:$A$2005,">="&B$5,Expenses!$A$6:$A$2005,"<"&EDATE(B$5,1)) -> 0 | C32: =SUMIFS(Expenses!$D$6:$D$2005,Expenses!$G$6:$G$2005,"Owner",Expenses!$A$6:$A$2005,">="&C$5,Expenses!$A$6:$A$2005,"<"&EDATE(C$5,1)) -> 0 | D32: =SUMIFS(Expenses!$D$6:$D$2005,Expenses!$G$6:$G$2005,"Owner",Expenses!$A$6:$A$2005,">="&D$5,Expenses!$A$6:$A$2005,"<"&EDATE(D$5,1)) -> 0 | E32: =SUMIFS(Expenses!$D$6:$D$2005,Expenses!$G$6:$G$2005,"Owner",Expenses!$A$6:$A$2005,">="&E$5,Expenses!$A$6:$A$2005,"<"&EDATE(E$5,1)) -> 0 | F32: =SUMIFS(Expenses!$D$6:$D$2005,Expenses!$G$6:$G$2005,"Owner",Expenses!$A$6:$A$2005,">="&F$5,Expenses!$A$6:$A$2005,"<"&EDATE(F$5,1)) -> 0 | G32: =SUMIFS(Expenses!$D$6:$D$2005,Expenses!$G$6:$G$2005,"Owner",Expenses!$A$6:$A$2005,">="&G$5,Expenses!$A$6:$A$2005,"<"&EDATE(G$5,1)) -> 0 | H32: =SUMIFS(Expenses!$D$6:$D$2005,Expenses!$G$6:$G$2005,"Owner",Expenses!$A$6:$A$2005,">="&H$5,Expenses!$A$6:$A$2005,"<"&EDATE(H$5,1)) -> 0 | I32: =SUMIFS(Expenses!$D$6:$D$2005,Expenses!$G$6:$G$2005,"Owner",Expenses!$A$6:$A$2005,">="&I$5,Expenses!$A$6:$A$2005,"<"&EDATE(I$5,1)) -> 0 | ... M32: =SUMIFS(Expenses!$D$6:$D$2005,Expenses!$G$6:$G$2005,"Owner",Expenses!$A$6:$A$2005,">="&M$5,Expenses!$A$6:$A$2005,"<"&EDATE(M$5,1)) -> 0 | N32: =SUM(B32:M32) -> 0
A33: Money left in business (net profit - capital - owner) | B33: =B28-B31-B32 -> 81180 | C33: =C28-C31-C32 -> 0 | D33: =D28-D31-D32 -> 0 | E33: =E28-E31-E32 -> 0 | F33: =F28-F31-F32 -> 0 | G33: =G28-G31-G32 -> 0 | H33: =H28-H31-H32 -> 0 | I33: =I28-I31-I32 -> 0 | ... N33: =N28-N31-N32 -> 81180
A34: Cumulative net profit | B34: =SUM($B$28:B28) -> 81180 | C34: =SUM($B$28:C28) -> 81180 | D34: =SUM($B$28:D28) -> 81180 | E34: =SUM($B$28:E28) -> 81180 | F34: =SUM($B$28:F28) -> 81180 | G34: =SUM($B$28:G28) -> 81180 | H34: =SUM($B$28:H28) -> 81180 | I34: =SUM($B$28:I28) -> 81180 | ... M34: =SUM($B$28:M28) -> 81180 | N34: =M34 -> 81180
A35: Performance and checks
A36: Average selling price | B36: =IF(B8=0,0,B10/B8) -> 540.11976 | C36: =IF(C8=0,0,C10/C8) -> 0 | D36: =IF(D8=0,0,D10/D8) -> 0 | E36: =IF(E8=0,0,E10/E8) -> 0 | F36: =IF(F8=0,0,F10/F8) -> 0 | G36: =IF(G8=0,0,G10/G8) -> 0 | H36: =IF(H8=0,0,H10/H8) -> 0 | I36: =IF(I8=0,0,I10/I8) -> 0 | ... N36: =IF(N8=0,0,N10/N8) -> 540.11976
A37: Actual ingredient + packaging cost per unit | B37: =IF(B8+B9=0,0,(B14+B15)/(B8+B9)) -> 0 | C37: =IF(C8+C9=0,0,(C14+C15)/(C8+C9)) -> 0 | D37: =IF(D8+D9=0,0,(D14+D15)/(D8+D9)) -> 0 | E37: =IF(E8+E9=0,0,(E14+E15)/(E8+E9)) -> 0 | F37: =IF(F8+F9=0,0,(F14+F15)/(F8+F9)) -> 0 | G37: =IF(G8+G9=0,0,(G14+G15)/(G8+G9)) -> 0 | H37: =IF(H8+H9=0,0,(H14+H15)/(H8+H9)) -> 0 | I37: =IF(I8+I9=0,0,(I14+I15)/(I8+I9)) -> 0 | ... N37: =IF(N8+N9=0,0,(N14+N15)/(N8+N9)) -> 0
A38: Planned cost per unit | B38: =Settings!$B$9 -> 150 | C38: =Settings!$B$9 -> 150 | D38: =Settings!$B$9 -> 150 | E38: =Settings!$B$9 -> 150 | F38: =Settings!$B$9 -> 150 | G38: =Settings!$B$9 -> 150 | H38: =Settings!$B$9 -> 150 | I38: =Settings!$B$9 -> 150 | ... N38: =Settings!$B$9 -> 150
A39: Average units per session | B39: =IF(B7=0,0,B8/B7) -> 41.75 | C39: =IF(C7=0,0,C8/C7) -> 0 | D39: =IF(D7=0,0,D8/D7) -> 0 | E39: =IF(E7=0,0,E8/E7) -> 0 | F39: =IF(F7=0,0,F8/F7) -> 0 | G39: =IF(G7=0,0,G8/G7) -> 0 | H39: =IF(H7=0,0,H8/H7) -> 0 | I39: =IF(I7=0,0,I8/I7) -> 0 | ... N39: =IF(N7=0,0,N8/N7) -> 41.75
A40: Plan units (months with sales) | B40: =IF(B7>0,Settings!$B$7,0) -> 1055 | C40: =IF(C7>0,Settings!$B$7,0) -> 0 | D40: =IF(D7>0,Settings!$B$7,0) -> 0 | E40: =IF(E7>0,Settings!$B$7,0) -> 0 | F40: =IF(F7>0,Settings!$B$7,0) -> 0 | G40: =IF(G7>0,Settings!$B$7,0) -> 0 | H40: =IF(H7>0,Settings!$B$7,0) -> 0 | I40: =IF(I7>0,Settings!$B$7,0) -> 0 | ... M40: =IF(M7>0,Settings!$B$7,0) -> 0 | N40: =SUM(B40:M40) -> 1055
A41: Units as % of plan | B41: =IF(B40=0,0,B8/B40) -> 0.15829384 | C41: =IF(C40=0,0,C8/C40) -> 0 | D41: =IF(D40=0,0,D8/D40) -> 0 | E41: =IF(E40=0,0,E8/E40) -> 0 | F41: =IF(F40=0,0,F8/F40) -> 0 | G41: =IF(G40=0,0,G8/G40) -> 0 | H41: =IF(H40=0,0,H8/H40) -> 0 | I41: =IF(I40=0,0,I8/I40) -> 0 | ... N41: =IF(N40=0,0,N8/N40) -> 0.15829384
A42: Stock checks flagged | B42: =COUNTIFS('Daily Sales'!$A$6:$A$1005,">="&B$5,'Daily Sales'!$A$6:$A$1005,"<"&EDATE(B$5,1),'Daily Sales'!$O$6:$O$1005,"CHECK") -> 0 | C42: =COUNTIFS('Daily Sales'!$A$6:$A$1005,">="&C$5,'Daily Sales'!$A$6:$A$1005,"<"&EDATE(C$5,1),'Daily Sales'!$O$6:$O$1005,"CHECK") -> 0 | D42: =COUNTIFS('Daily Sales'!$A$6:$A$1005,">="&D$5,'Daily Sales'!$A$6:$A$1005,"<"&EDATE(D$5,1),'Daily Sales'!$O$6:$O$1005,"CHECK") -> 0 | E42: =COUNTIFS('Daily Sales'!$A$6:$A$1005,">="&E$5,'Daily Sales'!$A$6:$A$1005,"<"&EDATE(E$5,1),'Daily Sales'!$O$6:$O$1005,"CHECK") -> 0 | F42: =COUNTIFS('Daily Sales'!$A$6:$A$1005,">="&F$5,'Daily Sales'!$A$6:$A$1005,"<"&EDATE(F$5,1),'Daily Sales'!$O$6:$O$1005,"CHECK") -> 0 | G42: =COUNTIFS('Daily Sales'!$A$6:$A$1005,">="&G$5,'Daily Sales'!$A$6:$A$1005,"<"&EDATE(G$5,1),'Daily Sales'!$O$6:$O$1005,"CHECK") -> 0 | H42: =COUNTIFS('Daily Sales'!$A$6:$A$1005,">="&H$5,'Daily Sales'!$A$6:$A$1005,"<"&EDATE(H$5,1),'Daily Sales'!$O$6:$O$1005,"CHECK") -> 0 | I42: =COUNTIFS('Daily Sales'!$A$6:$A$1005,">="&I$5,'Daily Sales'!$A$6:$A$1005,"<"&EDATE(I$5,1),'Daily Sales'!$O$6:$O$1005,"CHECK") -> 0 | ... M42: =COUNTIFS('Daily Sales'!$A$6:$A$1005,">="&M$5,'Daily Sales'!$A$6:$A$1005,"<"&EDATE(M$5,1),'Daily Sales'!$O$6:$O$1005,"CHECK") -> 0 | N42: =SUM(B42:M42) -> 0
...
